Workbook
Name Structure_Map: Overview!$D$80
Name Tab1_Map: Overview!$D$238
Name Tab2_Map: Overview!$D$265
Name Tab3_Map: Overview!$D$295
Name Tab4_Map: Overview!$D$326
Name Tab5_Map: Overview!$D$357
Name Tab6_Map: Overview!$D$386

Sheet Overview
A86: View detailed regulatory mapping for Tab 1 >
A93: View detailed regulatory mapping for Tab 2 >
A99: View detailed regulatory mapping for Tab 3 >
A104: View detailed regulatory mapping for Tab 4 >
A110: View detailed regulatory mapping for Tab 5 >
A116: View detailed regulatory mapping for Tab 6 >
A231: Return to: 3. Structure of the Workbook ^
E237: Area | F237: Specific FCA Provisions (examples) | G237: Key FCA Expectations | H237: How Tab 1 helps evidence this
E238: Consumer Duty – products & services; price & value; communications | F238: PRIN 2A – The Consumer Duty: PRIN 2A.3 Products and services outcome (design, target market, distribution). (FCA Handbook) PRIN 2A.4 Price and value outcome (reasonable relationship between price and benefits). (FCA Handbook) PRIN 2.1.1R (Principle 7) – information that is clear, fair and not misleading. (FCA) | G238: - Products must be fit for purpose and designed to meet the needs, characteristics and objectives of an identified target market. - Firms must ensure a reasonable relationship between price and value – no obvious structural unfairness or extraction. - Customers should be able to understand key features and limitations from the firm’s communications. (FCA Handbook) | H238: - Sections A & E assess token purpose, utility and economic design (allocations, vesting, emissions, incentives), helping show the token is not inherently misaligned with customer needs or structurally unfair on value. - Sections C & D assess token holder rights and the quality/completeness of disclosures (e.g. whitepaper), supporting evidence that material features, risks and limitations are not obscured and can be explained clearly to retail. - Overall, Tab 1 provides a documented basis that the token is coherent, explainable and not obviously exploitative, which you can cross-reference in Consumer Duty product & value assessments.
E239: Product governance – design, approval and understanding of instruments (PROD) | F239: PROD 3.2 – Product governance for manufacturers: e.g. PROD 3.2.1R / 3.2.3R – maintain, operate and review a product approval process for each product and significant adaptation. (FCA Handbook) PROD 3.3 – Product governance for distributors: PROD 3.3.1R and related rules – distributors must understand the financial instruments they distribute and assess compatibility with clients’ needs. (FCA Handbook) FCA MiFID II product governance review / good-practice commentary (e.g. 2021 multi-firm review). (FCA) | G239: - Manufacturers: operate a formal product approval process considering target market, risk/return profile and distribution strategy. - Distributors: understand product features, risks and costs and only distribute where compatible with the needs and objectives of the target market. - Maintain an evidence trail showing that products have been assessed and reviewed over time (not just one-off sign-off). (FCA Handbook) | H239: - Tab 1 functions as the front-end product approval template for tokens, capturing their purpose, governance, rights and economic model in a consistent way. - The questions force a structured articulation of how the token works, how value flows, who controls key decisions, and what holders actually get – satisfying the PROD expectation that distributors “understand the instruments” they sell. - Re-running Tab 1 when governance, tokenomics or rights change provides a repeatable review process you can point to in product governance/POG frameworks and product approval committee minutes.
E240: Governance & SMCR – SYSC systems and controls, risk identification and oversight | F240: SYSC 4.1.1R – General requirements: firms must have robust governance arrangements, including clear structures and effective processes to identify, manage, monitor and report the risks they are or might be exposed to. (FCA Handbook) SYSC 3.1 – Systems and controls: firms must take reasonable care to establish and maintain effective systems and controls for compliance with regulatory requirements and risk management. (Square Mile Research) SM&CR guidance emphasising Senior Managers’ responsibility for effective oversight of products and associated risks. (BDO) | G240: - Have formal processes and controls to identify and monitor product-level risks, not just business-line or balance-sheet risks. - Ensure Senior Managers can demonstrate they understand and have challenged significant new products and that decisions are evidenced. - Embed product and conduct risks into the firm’s overall risk management and governance framework. | H240: - Tab 1 gives a structured risk identification mechanism for token fundamentals and governance: numerical scores, risk bands, and a “weakest link” indicator for the domain. - The section-level summaries and narratives provide a concise briefing pack for Senior Managers and committees, making it easier to show that listing decisions were considered and challenged (rather than rubber-stamped). - As part of the wider engine, Tab 1 supports the argument that you have robust governance arrangements and systems and controls to identify and manage product-specific risks, in line with SYSC 4.1.1R and SYSC 3.1.
E241: FCA focus on product governance and value (cross-cutting guidance) | F241: FCA product governance / value publications and reviews, e.g.: - MiFID II product governance multi-firm review (2021). (FCA) - Consumer Duty and its impact on product governance and target market work (various guidance / good-practice papers). (DWF) | G241: - Firms should be able to demonstrate how they have assessed value, target market and product design, especially for complex / higher-risk products. - Supervisors expect documented frameworks rather than informal judgements, particularly for novel or high-risk asset classes like cryptoassets. | H241: - Tab 1 is a key part of your evidential framework for crypto tokens, showing that you have gone beyond surface-level marketing claims to interrogate fundamentals, governance and tokenomics. - Outputs from Tab 1 can be lifted directly into Product Approval Committee packs, listing committee papers, IA/product files and regulatory submissions to demonstrate that crypto products have been through the same, or stronger, governance as traditional products.
A258: Return to: 3. Structure of the Workbook ^
E264: Area | F264: Specific FCA Provisions (examples) | G264: Key FCA Expectations | H264: How Tab 2 helps evidence this
E265: Financial promotion regime – cryptoassets and high-risk investments | F265: FSMA 2000 s.21 – Financial promotion restriction: a person must not, in the course of business, communicate an invitation or inducement to engage in investment activity unless the promotion is issued or approved by an authorised person or an exemption applies. (Legislation.gov.uk) COBS 4 – Communicating with clients, including financial promotions: promotions must be fair, clear and not misleading and comply with detailed rules (e.g. risk warnings, prominence, appropriate balancing of benefits and risks). (FCA Handbook) PS23/6 – Financial promotion rules for cryptoassets and FG23/3: extend the financial promotion regime to qualifying cryptoassets, imposing RMMI-style requirements (risk warnings, 24-hour cooling off, appropriateness, banned incentives, etc.). (FCA) Crypto promotions rely on routes under FSMA and the FPO (e.g. newly introduced exemptions for FCA-registered crypto businesses). (FCA) | G265: - Firms must ensure that any cryptoasset promotion to UK consumers is lawfully communicated under s.21 FSMA, via an authorised person, an exemption, or another lawful route. - Promotions must meet high standards of clarity and risk disclosure (fair, clear, not misleading; prominent, prescribed warnings; appropriate framing of risks vs returns). - Cryptoassets treated as high-risk investments must comply with strengthened rules around risk warnings, incentives, cooling-off and appropriateness. (FCA) | H265: - Tab 2 captures how the token is being promoted to UK customers and under which lawful route (authorised firm promotion, s.21 approval, exemption or overseas-only marketing), giving you a structured record that the financial promotion restriction has been considered. - Questions around disclosure content, prominence of risk warnings, use of incentives, cooling-off and appropriateness allow you to benchmark the token’s promotional materials against the crypto financial promotion regime in PS23/6 / FG23-3 and the underlying COBS 4 standards. - The tab’s scoring and narrative provide an auditable explanation of why the firm believes the promotions are compliant, or why additional controls (re-wording, target-market limits, professional-only routes) are needed.
E266: Approval and ongoing oversight of financial promotions | F266: COBS 4.10 – Approving financial promotions: firms approving a promotion must take reasonable steps to ensure it complies with the rules and remains so for its lifetime. (FCA Handbook) COBS 4.11 – Record-keeping: financial promotions: firms must keep adequate records of promotions they communicate, approve or confirm compliance with. (FCA Handbook) FSMA 2023 – Financial promotion gateway (“approver permission”): new requirement for firms to obtain specific permission to approve promotions for unauthorised persons. (FCA) FCA cryptoasset financial promotions guidance emphasises the need for firms approving promotions to understand the token and associated risks. (Burges Salmon) | G266: - Firms that approve promotions must have appropriate expertise and due diligence processes to satisfy themselves the promotion is compliant on approval and remains compliant over time. - Firms must maintain records of approvals, underlying assessments and monitoring, enabling them to demonstrate why they considered a promotion compliant at the time. - Under the new gateway, only firms with the specific “approver permission” may approve promotions for unauthorised persons, and the FCA expects high standards of scrutiny, especially for cryptoassets. | H266: - Tab 2 provides a standardised due diligence record for each token’s regulatory/legal profile and promotional set-up. This can be cited as part of the file evidencing your s.21 approval or oversight of promotions. - Questions on regulatory route, risk classification, and disclosures demonstrate that the firm has considered the key issues the FCA expects approvers to address before signing off crypto promotions. - The tab’s outputs can be cross-referenced in your COBS 4.10/4.11 records and in your internal financial promotion approval logs, showing how each promotion was assessed in light of the token’s regulatory/legal risks.
E267: Regulatory perimeter & classification of the token / activities | F267: FSMA 2000 and the RAO – define “regulated activities” and “specified investments” (e.g. securities, units in collective investment schemes, contracts for differences, etc.). FCA perimeter guidance including PERG 2 & PERG 8 on the financial promotion regime and what constitutes “investment activity”. (sedric.ai) FCA and HM Treasury material on the future Designated Activities Regime (DAR) for cryptoassets under FSMA 2023, under which certain crypto activities will be designated and subject to activity-specific rules. (Taylor Wessing) | G267: - Firms must assess whether a token or associated activities fall inside or outside the current regulatory perimeter (e.g. security token vs unregulated cryptoasset vs e-money vs CIS / AIF structure). - Even where a token itself is unregulated, perimeter issues can arise (e.g. units in a CIS, operating a trading platform, custody, payment services). - As the DAR and other reforms are implemented, firms will be expected to understand whether their crypto offerings fall within designated activities and to comply with the associated rule-sets. | H267: - Tab 2 prompts a structured assessment of the token’s likely classification (security-like features, rights, redemption terms, profit-sharing, pooling of assets, etc.) and the associated regulated activities that may be triggered. - This gives you a documented, repeatable trail of the perimeter analysis that underpins your decision to treat a token as: - a regulated instrument (with full FSMA/COBS/PROD implications), - an unregulated cryptoasset subject to the financial promotion regime, or - part of a broader arrangement (e.g. pooled vehicles) that might itself be a regulated CIS. - As DAR and future rules come in, the same Tab 2 structure can be extended to track which designated activities are in scope and what additional legal/regulatory constraints apply.
E268: Consumer Duty & retail distribution – suitability, appropriateness and high-risk categorisation | F268: PRIN 2A – The Consumer Duty (especially: products & services, price & value, consumer understanding). (FCA Handbook) FCA high-risk investment / crypto promotion work, including the classification of qualifying cryptoassets as Restricted Mass Market Investments (RMMIs) with enhanced promotion rules. (FCA) COBS 10 & 10A – Appropriateness (for complex/high-risk investments) – assessing whether a non-advised client has the necessary experience and knowledge to understand the risks. (FCA Handbook) | G268: - Even where crypto activities themselves are not fully regulated yet, the Consumer Duty and strengthened financial promotion rules emphasise: - clear identification of target market vs restricted/professional-only distribution; - robust appropriateness tests for high-risk or complex products; - enhanced warnings and frictions (e.g. cooling-off) for RMMIs such as crypto. - Firms should be able to demonstrate why a given token is appropriate for a particular retail segment (or why retail access is restricted) in light of its risks and complexity. | H268: - Tab 2 consolidates your thinking on whether a given token: - should be treated as a high-risk investment for retail purposes, - should be accessible only to restricted / sophisticated / professional clients, or - should not be offered at all. - It links the token’s regulatory and legal profile to distribution and suitability decisions (e.g. requirement for appropriateness tests, extra risk warnings, or channel restrictions). - These outputs can be used to justify your target market definition, your use of appropriateness tests, and any distribution restrictions in internal Consumer Duty and product governance documentation.
E269: Cross-border and jurisdictional legal risk | F269: FCA Principles (e.g. Principle 1 – Integrity, Principle 2 – Due skill, care and diligence) and SYSC 6 expectations around having adequate compliance functions and controls to identify and manage legal/regulatory risks across jurisdictions. (FCA Handbook) Overseas regimes that may restrict marketing or availability of certain tokens to local investors (e.g. local securities or derivatives laws, bans, enforcement actions). | G269: - Firms are expected to avoid engaging in or facilitating activity that breaches local law in other jurisdictions, even if some aspects of the token are unregulated in the UK. - Compliance and legal teams must be able to identify where a token is subject to material overseas restrictions or enforcement, and decide whether and how to offer exposure from the UK. | H269: - Tab 2 includes questions on jurisdictional mapping, overseas regulatory actions and local restrictions affecting the token or its issuer. - This creates a central place where you record whether there are material overseas legal risks (e.g. securities enforcement, bans on retail marketing) that should influence your decision to list the token, how you structure access, or whether you apply additional warnings or exclusions for particular client segments or geographies.
A287: Return to: 3. Structure of the Workbook ^
E294: Area | F294: Specific FCA Provisions (examples) | G294: Key FCA Expectations | H294: How Tab 3 helps evidence this
E295: Core AML/CTF regime & firm-wide risk assessment | F295: Money Laundering, Terrorist Financing and Transfer of Funds (Information on the Payer) Regulations 2017 (MLRs) – e.g.: - Regulation 18 – firm-wide risk assessment of money laundering and terrorist financing risks. (Legislation.gov.uk) - Regulation 19 – policies, controls and procedures to mitigate and manage those risks. (Legislation.gov.uk) FCA Financial Crime Guide (FCG) and FG18/5 – guidance on systems and controls to counter financial crime, including market-related risks. (FCA Handbook) | G295: - Firms must identify, assess and understand their ML/TF risk profile, including new products and technologies, and maintain documented risk assessments. - Appropriate policies, controls and procedures must be implemented and kept up to date to mitigate identified risks. - New or developing technologies (such as cryptoassets) require a specific risk assessment and tailored controls under the risk-based approach. (Legislation.gov.uk) | H295: - Tab 3 provides a structured product-level ML/TF risk assessment for each token, feeding into your firm-wide Reg 18 risk assessment and product risk register. - Questions around anonymity features, obfuscation tools, typical use-cases and high-risk geographies show that you have explicitly considered ML/TF risk factors for this cryptoasset, not just for the customer base in general. - The scoring and risk banding can be referenced in your Reg 18 assessment and in the documentation of the AML risk classification for each token (e.g. “standard”, “elevated”, “intolerable”).
E296: Customer due diligence (CDD), enhanced due diligence (EDD) & high-risk factors | F296: MLRs 2017 – key CDD/EDD obligations: - Regulation 27–30 – customer due diligence and ongoing monitoring. - Regulation 33 – enhanced due diligence for higher-risk situations (including high-risk third countries, complex or unusually large transactions). (Legislation.gov.uk) - Regulation 35 – PEPs; Regulation 33–35 together set out higher-risk customer factors. (Legislation.gov.uk) JMLSG Guidance (e.g. Part I, Ch. 4 – risk-based approach) emphasises assessing ML/TF risk for new products and technologies. (jmlsg.org.uk) | G296: - Firms must perform CDD and adapt the depth of checks based on risk, applying EDD where higher risks are identified (e.g. high-risk countries, complex structures, unusual patterns). - For new products or technologies, firms must understand how those products can be used to obscure beneficial ownership, source of funds or transaction trails, and adjust CDD/EDD accordingly. - Ongoing monitoring must detect atypical patterns and trigger review or escalation. (Legislation.gov.uk) | H296: - Tab 3 analyses product-specific risk factors that drive the need for EDD: - embedded privacy features, mixers/bridges/ecosystem tools commonly used for obfuscation, - typical customer and transactional profiles, - links to typologies such as scams, darknet markets or ransomware. - By scoring these factors, Tab 3 gives concrete input to your CDD/EDD risk scoring models, helping justify when a token (or flows involving a token) should be treated as requiring EDD, additional monitoring rules, or even hard blocks in certain jurisdictions or counterparties.
E297: FCA cryptoasset AML/CTF registration and expectations | F297: FCA Cryptoassets: AML / CTF regime – cryptoasset businesses in scope must register with the FCA under the MLRs and comply with the regulations. (FCA) FCA guidance on what the FCA expects to see in an AML registration application for cryptoasset firms (understanding and implementing the MLRs, including risk assessments, CDD/EDD and monitoring). (FCA) | G297: - In-scope crypto businesses must show a comprehensive understanding of the UK AML regime and how it is applied in the context of their products and services. - Firms must have a robust financial crime framework tailored to crypto-specific risks (e.g. pseudonymous transactions, high-velocity flows, cross-border activity). - Supervisors expect firms to evidence product-specific ML/TF risk assessment rather than generic AML boilerplate. (FCA) | H297: - Tab 3 evidences that your firm has gone beyond generic AML policy and carried out a cryptoasset-specific risk assessment at the individual token level. - It helps demonstrate to the FCA (or internal audit) that the firm understands: - which tokens are higher-risk from an ML/TF perspective, - how those risks are mitigated (e.g. venue choice, monitoring scenarios, thresholds, restricted jurisdictions), and - where the firm may decide not to list or to delist a token. - This can be referenced in your FCA registration file and ongoing supervisory interactions as evidence of a structured financial crime control environment around crypto offerings.
E298: Sanctions compliance – UK sanctions framework & OFSI guidance | F298: Sanctions and Anti-Money Laundering Act 2018 – primary legislation for the UK’s autonomous sanctions regimes. (Legislation.gov.uk) UK financial sanctions general guidance from OFSI and HM Treasury (how to comply with financial sanctions, screening expectations, asset freezes, reporting). (GOV.UK) Wider guidance and commentary on the UK sanctions regime (e.g. Law Society guidance). (Law Society) | G298: - Firms must ensure they do not: - deal with sanctioned persons or entities, - make funds or economic resources available, directly or indirectly, to designated persons, or - participate in arrangements that circumvent sanctions. - Appropriate screening and controls must be in place for customers, counterparties, and (for crypto) potentially for wallets/addresses, protocols or projects that are the subject of sanctions or sectoral measures. (GOV.UK) | H298: - Tab 3 contains questions specifically focused on sanctions exposure, such as: - whether relevant token contracts, treasuries or major counterparties are linked to designated persons or sanctioned jurisdictions; - the presence of OFAC/UK-sanctioned addresses or entities in the project’s history or ecosystem; - whether the token is widely used in typologies that overlap with sanctions evasion. - By assigning a sanctions risk score and band, Tab 3 gives a transparent basis for deciding: - whether to permit any activity involving the token, - whether to limit access (e.g. no support for self-hosted wallets in particular jurisdictions), and - how to parameterise sanctions screening and alerts for flows involving that token.
E299: Financial crime systems & controls – SYSC 6 | F299: SYSC 6.1.1R – firms must establish, implement and maintain adequate policies and procedures to ensure compliance with obligations under the regulatory system, including countering the risk that the firm might be used to further financial crime. (FCA Handbook) FCA Financial Crime Guide (FCG) and related FG18/5 guidance on financial crime systems and controls, including application of SYSC 6.1.1R. (FCA Handbook) | G299: - Firms must have effective systems and controls proportionate to the nature, scale and complexity of their activities, including products and services that present higher financial crime risk (such as cryptoassets). - They should be able to demonstrate how they identify, assess and mitigate financial crime risks at the product, customer and transaction levels. - Supervisors place particular scrutiny on how new products and technologies are risk assessed and embedded into the financial crime framework. (FCA Handbook) | H299: - Tab 3 acts as a product-level financial crime risk tool within your wider SYSC 6 framework. - It documents, in a consistent and repeatable way, the key ML/TF and sanctions risk factors for each token and assigns a risk band that can feed into: - onboarding decisions (list vs do not list), - monitoring rules and thresholds (e.g. stricter surveillance for higher-risk tokens), and - periodic re-assessment cycles. - This can be pointed to in your SYSC 6 documentation and financial crime policies as the mechanism by which crypto products are brought within the firm’s risk identification, assessment and mitigation processes.
E300: International standards & typologies (FATF, JMLSG, etc.) | F300: FATF Recommendations on virtual assets (VAs) and VASPs, including risk-based approach, Travel Rule, and expectations around VA-specific ML/TF risks. (Reflected in UK implementation via MLRs and FCA guidance.) (ICAEW) JMLSG guidance on risk-based approach for new products and technologies (Part I, Ch. 4). (jmlsg.org.uk) | G300: - Regulators expect firms to have regard to international standards on cryptoasset ML/TF risk, especially FATF’s VA/VASP guidance. - Firms should understand and respond to emerging typologies (e.g. mixing, DeFi, cross-chain bridges, ransomware, darknet markets) and not treat crypto like a simple extension of fiat payments. | H300: - Tab 3 explicitly incorporates crypto-specific typologies and technology risks (e.g. mixers, privacy protocols, DeFi exploits, high-risk venues) into its scoring, aligning your analysis with emerging FATF/JMLSG expectations. - This makes it easier, in audits or supervisory visits, to show that your AML/CTF assessments for cryptoassets are aligned with current international standards and not based on outdated or purely fiat-centric assumptions.
A317: Return to: 3. Structure of the Workbook ^
E325: Area | F325: Specific FCA Provisions (examples) | G325: Key FCA Expectations | H325: How Tab 4 helps evidence this
E326: Systems and controls for technology & operational risk (SYSC) | F326: SYSC 3.1.1R – firms must take reasonable care to establish and maintain effective systems and controls for compliance with regulatory obligations and for managing risk. SYSC 4.1.1R – firms must have robust governance arrangements, including effective processes to identify, manage, monitor and report risks. SYSC 13 & 13.7 (for certain firms) – additional expectations around operational risk and business continuity. | G326: - Technology and operational arrangements (including those supporting crypto services) must be fit for purpose, controlled, and subject to appropriate risk management. - Firms must be able to identify and monitor key operational/technical risks in the products they offer, not just in their own internal IT stack. - Senior management should be able to explain how technical risk in products is understood, monitored and reflected in risk appetite and controls. | H326: - Tab 4 gives a structured assessment of protocol and smart contract security, feeding directly into the firm’s SYSC 3/4 view of operational risk associated with the token. - Questions around vulnerability management, incident history, governance controls and resilience build a documented record of the technical risks you are accepting by listing/supporting this token. - The resulting scores and risk bands can be referenced in risk appetite discussions, product approval papers and the operational risk register as evidence that crypto product technical risks are being actively assessed.
E327: Operational resilience – important business services and impact of disruption | F327: FCA Operational Resilience framework (PS21/3 and related rules in the FCA Handbook – primarily in SYSC and the Operational Resilience sourcebook for in-scope firms): firms must identify important business services, set impact tolerances and ensure they can remain within those tolerances under severe but plausible disruptions. | G327: - Firms must understand how reliance on particular technologies, infrastructures or third-party services could cause intolerable harm to customers or market integrity if they fail. - Crypto-related services (e.g. custody, trading, staking) that are “important business services” require particular attention to resilience and failure modes. - There should be a clear view of how protocol-level failures or exploits could affect the firm’s ability to deliver services within impact tolerances. | H327: - Tab 4 helps identify tokens where protocol or contract weaknesses could realistically cause service disruption (e.g. trading halts, frozen funds, permanent loss) for your clients. - Where a token underpins an important business service (e.g. major trading pair, staking product), Tab 4 scores and narratives inform your operational resilience mapping, by documenting the likelihood and impact of technical failure. - These insights can be used to support decisions such as position limits, venue selection, contingency plans and disclosure in operational resilience documentation.
E328: Outsourcing, third-party and dependency risk | F328: SYSC 8 – outsourcing: requires that where a firm outsources critical or important operational functions, it must ensure the service provider has the ability, capacity and authorisation to carry out the functions reliably and professionally, and that the firm remains responsible for compliance. FCA outsourcing / third-party risk guidance emphasises understanding dependencies and ensuring appropriate oversight and exit strategies. | G328: - Firms must identify and manage critical dependencies on third-party providers (including technology providers, infrastructure, and crucial external services such as oracles or bridges). - Outsourcing or relying on third parties does not dilute the firm’s responsibility; firms must ensure they have adequate oversight, contingency and control. | H328: - Tab 4 captures key technical dependencies for each token (e.g. reliance on a specific oracle network, bridge, centralised sequencer, governance admin key, custodian or infrastructure provider). - It allows you to flag tokens where a single failure point (e.g. centralised multisig, unaudited bridge, off-chain oracle dependency) creates an unacceptable level of dependency risk. - You can use the Tab 4 outputs to explain, in your outsourcing/third-party risk framework, why certain tokens are restricted, require additional monitoring, or are only supported on particular venues or custody arrangements.
E329: Cyber & information security expectations | F329: FCA guidance and SYSC provisions emphasising IT and cyber security as part of effective systems and controls (e.g. FCG cyber guidance, thematic reviews on cyber and technology resilience). PRA/FCA material on cyber risk (e.g. cyber resilience statements, Dear CEO letters) often stresses the need for robust protection against cyber attacks and fraud. | G329: - Firms must take steps to ensure that IT environments and interfaces with external systems (including crypto protocols, APIs, nodes, wallets) are secure. - Where a product relies on external protocols and smart contracts, firms should understand key vulnerability vectors (e.g. admin key compromise, oracle manipulation, re-entrancy exploits) and reflect them in risk management. | H329: - Tab 4 surfaces whether a token’s protocol and contracts have a history of exploits or critical vulnerabilities, whether security best practices (e.g. audited, open-source, peer-reviewed code) are in place, and how quickly issues have been remediated in the past. - This allows your IT/cyber risk function and product owners to see where technical risk is particularly acute and where additional controls (e.g. limited functionality, enhanced monitoring, no leverage or derivatives on that token) may be required. - It also creates a record that cyber/technical risk has been considered at product level, not just at infrastructure level.
E330: Market integrity and conduct – impact of technical design on fairness and manipulation | F330: Principles for Businesses – particularly: - Principle 1 (Integrity) – conducting business with integrity. - Principle 2 (Skill, care and diligence) – managing products and risks competently. FCA market abuse / market integrity expectations (while the formal UK MAR regime may not apply directly to unregulated cryptoassets, the FCA expects firms to manage market integrity and abuse risks in line with their authorisations and permissions). | G330: - Firms are expected not to facilitate markets or products that are structurally prone to abuse or unfair outcomes, particularly where technical design encourages manipulation or unfair advantage. - Even where a specific regime (like MAR) is not fully applicable, firms must consider conduct and integrity risks arising from product structures and protocols (e.g. privileged insiders, upgrade powers, oracle design). | H330: - Tab 4 includes questions on upgrade and control mechanisms, oracle design, admin keys and governance rights, which affect the potential for technical manipulation (e.g. changing rules mid-game, pausing contracts, shutting out users). - By scoring these factors, you can distinguish between tokens with robust, decentralised, transparent technical control structures and those where a small group can materially change or halt the protocol, raising integrity concerns. - This supports conduct and market integrity obligations by demonstrating that technical features that could facilitate unfair practices have been explicitly considered before listing.
E331: Consumer Duty – reliability and foreseeable harm from technical failure | F331: PRIN 2A – Consumer Duty, especially: - Products and services outcome (PRIN 2A.3) – products should function as anticipated and deliver outcomes in line with customers’ needs. - Consumer support / foreseeable harm concepts – firms should avoid causing foreseeable harm through poor product design or unreliable services. | G331: - Firms should not offer products where foreseeable and material technical failures are likely to cause harm (e.g. repeated contract exploits, unsafe bridges, known critical vulnerabilities). - Where technical risk is material, it should be reflected in product design, disclosures, restrictions, and ongoing oversight. | H331: - Tab 4 gives an explicit, quantitative view of foreseeable technical harms: probability and impact of exploit, contract failure, or protocol malfunction. - This supports Consumer Duty by allowing you to show that you identified foreseeable technical harms, assessed their severity, and either: - mitigated them (through controls, disclosures, product design), or - decided not to offer or to withdraw exposure to certain tokens. - The Tab 4 narrative can be incorporated into Duty-focused product reviews and outcome assessments.
A349: Return to: 3. Structure of the Workbook ^
E356: Area | F356: Specific FCA Provisions (examples) | G356: Key FCA Expectations | H356: How Tab 5 helps evidence this
E357: Market integrity & market abuse (even where MAR doesn’t strictly apply) | F357: FCA Market Abuse Regulation (MAR) material – MAR aims to increase market integrity and investor protection by tackling insider dealing, unlawful disclosure and market manipulation.(FCA) FCA market abuse pages stress firms’ responsibility for safeguards against abusive behaviours.(FCA) FCA DP24/4 – Regulating cryptoassets: Admissions & Disclosures and Market Abuse Regime for Cryptoassets (MARC) – developing a crypto-specific market abuse regime that mirrors MAR-style outcomes.(FCA) | G357: - Firms should not facilitate trading environments that are systemically prone to abuse (e.g. persistent manipulation, wash trading, insider dealing), even where MAR technically applies only to certain instruments/venues. - Cryptoasset markets are increasingly expected to align with market integrity standards similar to those under MAR, especially as a dedicated MARC framework is developed. - Firms should have arrangements and surveillance to identify unusual or abusive patterns and respond appropriately.(FCA) | H357: - Tab 5 specifically looks for indicators of wash trading, spoofing-style activity, extreme concentration of volume or holdings, and structurally weak venues, giving a transparent assessment of the market integrity for each token. - High scores in the “manipulation/abuse” questions provide a clear signal that the token’s trading environment may be inconsistent with the FCA’s expectations on orderly and abuse-resistant markets, even if the token/venue is formally outside MAR. - These outputs support your argument that you either: - apply enhanced surveillance and restrictions for certain tokens; or - decline to list them where market integrity is too weak.
E358: Best execution, order handling and fair pricing / liquidity | F358: COBS 11 – Dealing and managing: - COBS 11.2A (Best execution – MiFID provisions) – firms must take all reasonable steps to obtain the best possible result for clients, considering price, costs, speed, likelihood of execution/settlement and other relevant factors.(beta-handbook.fca.org.uk) - COBS 11.3 – client order handling rules (fair, prompt, expeditious execution; avoiding adverse impact on clients). | G358: - Where best execution obligations apply, firms must be able to demonstrate that they considered liquidity, spreads, depth and execution likelihood across different venues when designing execution arrangements. - Even outside strict MiFID best execution scope, firms promoting trading in certain assets are expected to consider whether the trading environment produces fair pricing and reasonable execution outcomes. | H358: - Tab 5’s focus on liquidity depth, spreads, slippage and venue quality gives a structured view of whether it is realistically possible to achieve “good” execution outcomes in the token under plausible trade sizes. - The scores highlight tokens where liquidity is so thin or fragmented that material slippage or failed execution is likely, which can be factored into: - your best execution policy, - internal lists of tokens permitted for execution, and - position size / ticket size guidance. - This helps demonstrate that you have considered liquidity and execution factors in line with COBS 11.2A/11.3, even where the token trades on venues technically outside MiFID scope.
E359: Consumer Duty – price & value, foreseeable harm from illiquidity and volatile trading conditions | F359: PRIN 2A – Consumer Duty: - PRIN 2A.3 Products and services outcome – products should work as reasonably expected and be designed for a defined target market. - PRIN 2A.4 Price and value outcome – there should be a reasonable relationship between price and benefits; poor value can arise where trading conditions impose excessive friction.(FCA) FCA commentary on high-risk investments and crypto promotions emphasises the need to consider liquidity, volatility and exit risk when assessing suitability for retail investors.(FCA) | G359: - Firms should not put customers into products where foreseeable trading conditions (e.g. chronic illiquidity, extreme slippage, inability to exit) are likely to cause foreseeable harm or poor value. - Liquidity, volatility and depth should be factored into decisions about whether a cryptoasset is appropriate for retail, restricted to certain client types, or not offered at all. | H359: - Tab 5 quantifies liquidity and exit risk (spreads, depth, ability to execute in typical trade sizes) and flags tokens where customers may struggle to exit positions at a fair price. - It also considers volatility / market quality elements that can make realisable value materially different from notional value (e.g. manipulated pumps, thin order books). - These insights support your Consumer Duty work by linking the economic experience clients actually get in the market to your product and value assessments – and can justify limiting or prohibiting retail access where market conditions are consistently poor.
...

Sheet Token Fundamentals & Governance
A1: Question_ID | B1: Question_Text | C1: Raw_Response | D1: Confidence | E1: Raw_Points | F1: Reliability_Modifier | G1: Reliability_Adjusted_Points | H1: Source_Citations | I1: Source_Dates | J1: Accessed_Dates | K1: Most_Recent_Source_Date | L1: Days_Since_Source | M1: Staleness_Class | N1: Staleness_Penalty | O1: Final_Score | P1: Board_Escalation_Flag | Q1: Trigger_Rule_Description | R1: Narrative_Justification | S1: Debug Notes
B2: A. Purpose & Utility
A4: A1.1 | B4: Primary token category (Primary & Secondary). Answer using exactly this format: "Primary: <one of: Native L1, Gas/Fee, Governance, Utility, LP/AMM, Stablecoin, Asset-Backed, Meme/Narrative, Other>; Secondary: <one of the same list>". Do not add explanations or extra words. | C4: Primary: Native L1; Secondary: Gas/Fee | D4: High | E4: =IF(ISNUMBER(SEARCH("Primary: Meme",C4)),22,IF(ISNUMBER(SEARCH("Primary: Asset",C4)),18,IF(ISNUMBER(SEARCH("Primary: Liquidity",C4)),15,IF(ISNUMBER(SEARCH("Primary: Governance",C4)),12,IF(ISNUMBER(SEARCH("Primary: Utility",C4)),7,IF(ISNUMBER(SEARCH("Primary: Gas",C4)),5,IF(ISNUMBER(SEARCH("Primary: Native",C4)),0,IF(ISNUMBER(SEARCH("Primary: Stablecoin",C4)),5,IF(ISNUMBER(SEARCH("Primary: LP/AMM",C4)),15,IF(C4="","",10)))))))))) -> 0 | F4: =IF(D4="High",0,IF(D4="Medium",0.05,IF(D4="Low",0.1,IF(D4="Unknown",0.15,"")))) -> 0 | G4: =E4*(1+F4) -> 0 | H4: https://docs.avax.network/learn/avalanche/avax; https://docs.avax.network/build/subnet/elastic-subnets/avalanche-c-chain | I4: 2023-06-01; 2023-05-01 | J4: 2025-12-12; 2025-12-12 | K4: =IF(I4="","",MAX(IFERROR(DATEVALUE(TRIM(MID(SUBSTITUTE(I4,";",REPT(" ",50)),1,50))),0),IFERROR(DATEVALUE(TRIM(MID(SUBSTITUTE(I4,";",REPT(" ",50)),51,50))),0),IFERROR(DATEVALUE(TRIM(MID(SUBSTITUTE(I4,";",REPT(" ",50)),101,50))),0),IFERROR(DATEVALUE(TRIM(MID(SUBSTITUTE(I4,";",REPT(" ",50)),151,50))),0),IFERROR(DATEVALUE(TRIM(MID(SUBSTITUTE(I4,";",REPT(" ",50)),201,50))),0),IFERROR(DATEVALUE(TRIM(MID(SUBSTITUTE(I4,";",REPT(" ",50)),251,50))),0),IFERROR(DATEVALUE(TRIM(MID(SUBSTITUTE(I4,";",REPT(" ",50)),301,50))),0),IFERROR(DATEVALUE(TRIM(MID(SUBSTITUTE(I4,";",REPT(" ",50)),351,50))),0),IFERROR(DATEVALUE(TRIM(MID(SUBSTITUTE(I4,";",REPT(" ",50)),401,50))),0),IFERROR(DATEVALUE(TRIM(MID(SUBSTITUTE(I4,";",REPT(" ",50)),451,50))),0))) -> 45078 | L4: =IF(K4="","",TODAY()-K4) -> 926 | M4: Evergreen–No Penalty | N4: =IF(M4="","",IF(L4="",INDEX($F$92:$F$95,MATCH(M4,$C$92:$C$95,0)),IF(L4<=INDEX($D$92:$D$95,MATCH(M4,$C$92:$C$95,0)),0,IF(L4<=INDEX($E$92:$E$95,MATCH(M4,$C$92:$C$95,0)),INDEX($F$92:$F$95,MATCH(M4,$C$92:$C$95,0)),INDEX($G$92:$G$95,MATCH(M4,$C$92:$C$95,0)))))) -> 0 | O4: =G4+N4 -> 0 | P4: No Review | Q4: Helper row; scored via primary role only. | R4: AVAX is the native token of the Avalanche network, required for staking/validation and used as the base unit of account across its subnets, making it a Native L1 asset. It is also the primary gas and transaction fee token on the C-Chain and other EVM-compatible subnets, so Gas/Fee is the most appropriate secondary category.
A5: A1.2 | B5: Stated value proposition (one-sentence summary). | C5: Avalanche aims to provide a highly scalable, low-latency, and customizable Layer-1 blockchain platform—powered by its Avalanche consensus and subnet architecture—for deploying decentralized applications and custom blockchains with near-instant finality and low fees. | D5: High | E5: 0 | F5: =IF(D5="High",0,IF(D5="Medium",0.05,IF(D5="Low",0.1,IF(D5="Unknown",0.15,"")))) -> 0 | G5: =E5*(1+F5) -> 0 | H5: https://www.avax.network/about/avalanche-avax/; https://www.avax.network/about/press/introduction-to-avalanche/; https://www.avax.network/about/consensus | I5: 2024-11-15; 2024-10-20; 2024-10-01 | J5: 2025-12-12; 2025-12-12; 2025-12-12 | K5: =IF(I5="","",MAX(IFERROR(DATEVALUE(TRIM(MID(SUBSTITUTE(I5,";",REPT(" ",50)),1,50))),0),IFERROR(DATEVALUE(TRIM(MID(SUBSTITUTE(I5,";",REPT(" ",50)),51,50))),0),IFERROR(DATEVALUE(TRIM(MID(SUBSTITUTE(I5,";",REPT(" ",50)),101,50))),0),IFERROR(DATEVALUE(TRIM(MID(SUBSTITUTE(I5,";",REPT(" ",50)),151,50))),0),IFERROR(DATEVALUE(TRIM(MID(SUBSTITUTE(I5,";",REPT(" ",50)),201,50))),0),IFERROR(DATEVALUE(TRIM(MID(SUBSTITUTE(I5,";",REPT(" ",50)),251,50))),0),IFERROR(DATEVALUE(TRIM(MID(SUBSTITUTE(I5,";",REPT(" ",50)),301,50))),0),IFERROR(DATEVALUE(TRIM(MID(SUBSTITUTE(I5,";",REPT(" ",50)),351,50))),0),IFERROR(DATEVALUE(TRIM(MID(SUBSTITUTE(I5,";",REPT(" ",50)),401,50))),0),IFERROR(DATEVALUE(TRIM(MID(SUBSTITUTE(I5,";",REPT(" ",50)),451,50))),0))) -> 45611 | L5: =IF(K5="","",TODAY()-K5) -> 393 | M5: Evergreen–No Penalty | N5: =IF(M5="","",IF(L5="",INDEX($F$92:$F$95,MATCH(M5,$C$92:$C$95,0)),IF(L5<=INDEX($D$92:$D$95,MATCH(M5,$C$92:$C$95,0)),0,IF(L5<=INDEX($E$92:$E$95,MATCH(M5,$C$92:$C$95,0)),INDEX($F$92:$F$95,MATCH(M5,$C$92:$C$95,0)),INDEX($G$92:$G$95,MATCH(M5,$C$92:$C$95,0)))))) -> 0 | O5: =G5+N5 -> 0 | P5: No Review | Q5: Descriptive only; no escalation. | R5: Avalanche’s own materials describe it as an open, programmable, highly scalable platform offering high throughput, sub‑second or near‑instant finality, low fees, and support for custom blockchains/subnets for diverse dApps and asset tokenization, which together form its core value proposition.
A6: A1.3 | B6: Does real-world usage match the stated purpose? (Yes / Partial / No). | C6: Partial | D6: High | E6: =IF(C6="Yes",0,IF(C6="Partial",10,IF(C6="No",20,""))) -> 10 | F6: =IF(D6="High",0,IF(D6="Medium",0.05,IF(D6="Low",0.1,IF(D6="Unknown",0.15,"")))) -> 0 | G6: =E6*(1+F6) -> 10 | H6: https://www.avax.network/about/avalanche-avax/; https://messari.io/report/state-of-avalanche-q3-2024; https://blockchainreporter.net/avalanche-tvl-hits-1-74b-top-10-projects-dominating-the-ecosystem/ | I6: 2025-05-14; 2024-10-15; 2024-02-01 | J6: 2025-12-12; 2025-12-12; 2025-12-12 | K6: =IF(I6="","",MAX(IFERROR(DATEVALUE(TRIM(MID(SUBSTITUTE(I6,";",REPT(" ",50)),1,50))),0),IFERROR(DATEVALUE(TRIM(MID(SUBSTITUTE(I6,";",REPT(" ",50)),51,50))),0),IFERROR(DATEVALUE(TRIM(MID(SUBSTITUTE(I6,";",REPT(" ",50)),101,50))),0),IFERROR(DATEVALUE(TRIM(MID(SUBSTITUTE(I6,";",REPT(" ",50)),151,50))),0),IFERROR(DATEVALUE(TRIM(MID(SUBSTITUTE(I6,";",REPT(" ",50)),201,50))),0),IFERROR(DATEVALUE(TRIM(MID(SUBSTITUTE(I6,";",REPT(" ",50)),251,50))),0),IFERROR(DATEVALUE(TRIM(MID(SUBSTITUTE(I6,";",REPT(" ",50)),301,50))),0),IFERROR(DATEVALUE(TRIM(MID(SUBSTITUTE(I6,";",REPT(" ",50)),351,50))),0),IFERROR(DATEVALUE(TRIM(MID(SUBSTITUTE(I6,";",REPT(" ",50)),401,50))),0),IFERROR(DATEVALUE(TRIM(MID(SUBSTITUTE(I6,";",REPT(" ",50)),451,50))),0))) -> 45791 | L6: =IF(K6="","",TODAY()-K6) -> 213 | M6: Operational–Medium | N6: =IF(M6="","",IF(L6="",INDEX($F$92:$F$95,MATCH(M6,$C$92:$C$95,0)),IF(L6<=INDEX($D$92:$D$95,MATCH(M6,$C$92:$C$95,0)),0,IF(L6<=INDEX($E$92:$E$95,MATCH(M6,$C$92:$C$95,0)),INDEX($F$92:$F$95,MATCH(M6,$C$92:$C$95,0)),INDEX($G$92:$G$95,MATCH(M6,$C$92:$C$95,0)))))) -> 3 | O6: =G6+N6 -> 13 | P6: =IF(AND(C6="No",D6="Low"),"Review Required","No Review") -> No Review | Q6: Escalate only if stated purpose does not match real-world usage AND confidence is Low. | R6: Avalanche’s stated purpose is to be a high‑throughput, low‑latency, programmable platform for DeFi, dApps, and custom blockchains, ultimately aiming to tokenize global assets. In practice, it has significant DeFi adoption (Aave, Benqi, Trader Joe/LFJ, GMX) with TVL in the low‑billion‑dollar range and active usage of subnets, including gaming and real‑world‑asset tokenization like BlackRock‑backed BUIDL. This shows strong alignment with its DeFi/dApp and subnet vision, but its broader ambition to digitize “all the world’s assets” remains only partially realized, so alignment is best described as Partial.
A7: A1.4 | B7: List current real use cases (bulleted). | C7: - Decentralized finance (DeFi): Lending, DEXs, stablecoin settlement, and yield protocols on the C‑Chain (e.g., Aave, Curve and broader DeFi activity supported by growing on‑chain stablecoin supply). - Gaming and metaverse: High‑throughput game subnets such as DeFi Kingdoms’ DFK Chain, Shrapnel, Gunzilla/Off the Grid and Beam, using AVAX infrastructure for in‑game assets and transactions. - Enterprise / institutional finance: Tokenization and settlement of financial instruments and funds on Avalanche Evergreen/regulated subnets by institutions like JP Morgan, Citi, HSBC, VanEck and others (e.g., tokenized treasuries, short‑term debt, private equity, portfolio management). - Real‑world asset (RWA) tokenization: Tokenized real estate, film rights, structured finance products (e.g., IntainMARKETS), carbon and other assets issued on Avalanche subnets and the C‑Chain. - Ticketing & loyalty: Enterprise partners (e.g., Dreamus/OK Cashbag, Tixbase/PASSO) using Avalanche to issue verifiable event tickets and loyalty benefits, reducing fraud and enabling secondary markets. - Public sector and registries: Projects like the California DMV’s pilot to put vehicle titles and transfers on Avalanche infrastructure. - NFTs, collectibles & media: NFT marketplaces and media projects using Avalanche for digital collectibles, creator monetization and related Web3 experiences. - Core network utility: AVAX used as gas, for staking/validation, and for securing and participating in subnets, which power many of the above applications. | D7: High | E7: =IF(C7="","",IF(((LEN(C7)-LEN(SUBSTITUTE(C7,",","")))+(LEN(C7)-LEN(SUBSTITUTE(C7,";","")))+(LEN(C7)-LEN(SUBSTITUTE(C7,CHAR(10),""))))>=1,0,10)) -> 0 | F7: =IF(D7="High",0,IF(D7="Medium",0.05,IF(D7="Low",0.1,IF(D7="Unknown",0.15,"")))) -> 0 | G7: =E7*(1+F7) -> 0 | H7: https://www.avax.network/about/blog/7-avalanche-use-cases/; https://levex.com/en/blog/avalanche-guide; https://ambcrypto.com/blog/what-is-avax-avalanche-crypto-guide/ | I7: 2025-11-20; 2025-12-01; 2025-06-01 | J7: 2025-12-12; 2025-12-12; 2025-12-12 | K7: =IF(I7="","",MAX(IFERROR(DATEVALUE(TRIM(MID(SUBSTITUTE(I7,";",REPT(" ",50)),1,50))),0),IFERROR(DATEVALUE(TRIM(MID(SUBSTITUTE(I7,";",REPT(" ",50)),51,50))),0),IFERROR(DATEVALUE(TRIM(MID(SUBSTITUTE(I7,";",REPT(" ",50)),101,50))),0),IFERROR(DATEVALUE(TRIM(MID(SUBSTITUTE(I7,";",REPT(" ",50)),151,50))),0),IFERROR(DATEVALUE(TRIM(MID(SUBSTITUTE(I7,";",REPT(" ",50)),201,50))),0),IFERROR(DATEVALUE(TRIM(MID(SUBSTITUTE(I7,";",REPT(" ",50)),251,50))),0),IFERROR(DATEVALUE(TRIM(MID(SUBSTITUTE(I7,";",REPT(" ",50)),301,50))),0),IFERROR(DATEVALUE(TRIM(MID(SUBSTITUTE(I7,";",REPT(" ",50)),351,50))),0),IFERROR(DATEVALUE(TRIM(MID(SUBSTITUTE(I7,";",REPT(" ",50)),401,50))),0),IFERROR(DATEVALUE(TRIM(MID(SUBSTITUTE(I7,";",REPT(" ",50)),451,50))),0))) -> 45992 | L7: =IF(K7="","",TODAY()-K7) -> 12 | M7: Operational–Medium | N7: =IF(M7="","",IF(L7="",INDEX($F$92:$F$95,MATCH(M7,$C$92:$C$95,0)),IF(L7<=INDEX($D$92:$D$95,MATCH(M7,$C$92:$C$95,0)),0,IF(L7<=INDEX($E$92:$E$95,MATCH(M7,$C$92:$C$95,0)),INDEX($F$92:$F$95,MATCH(M7,$C$92:$C$95,0)),INDEX($G$92:$G$95,MATCH(M7,$C$92:$C$95,0)))))) -> 0 | O7: =G7+N7 -> 0 | P7: No Review | Q7: No trigger; used by A1.5/A3.1. | R7: Bullets summarize major categories of live Avalanche usage across DeFi, gaming subnets, institutional tokenization/RWAs, ticketing/loyalty, public registries, NFTs, and core network functions. Each cited source directly documents concrete applications or institutional integrations rather than hypothetical plans, supporting that these are current real use cases.
A8: A1.5 | B8: Identify and weight the main user groups of the token. Answer only in this format, using up to three groups: "<Group1> (primary), <Group2> (secondary), <Group3> (minor)". Choose user groups from: Developers, Validators, Retail, Institutions, Protocol integrators, Speculators. If speculators are only a minor group, write "Speculators (minor)". If they are a major driver, write "Speculators (primary)". Do not add any other words or explanation. | C8: Retail (primary), Developers (secondary), Speculators (minor) | D8: Medium | E8: =IF(C8="","",IF(ISNUMBER(SEARCH("Speculators (primary)",C8)),20,IF(ISNUMBER(SEARCH("Speculators (secondary)",C8)),15,IF(ISNUMBER(SEARCH("Speculators (minor)",C8)),10,IF(OR(ISNUMBER(SEARCH("Retail",C8)),ISNUMBER(SEARCH("Institutions",C8))),5,0))))) -> 10 | F8: =IF(D8="High",0,IF(D8="Medium",0.05,IF(D8="Low",0.1,IF(D8="Unknown",0.15,"")))) -> 0.05 | G8: =E8*(1+F8) -> 10.5 | K8: =IF(I8="","",MAX(IFERROR(DATEVALUE(TRIM(MID(SUBSTITUTE(I8,";",REPT(" ",50)),1,50))),0),IFERROR(DATEVALUE(TRIM(MID(SUBSTITUTE(I8,";",REPT(" ",50)),51,50))),0),IFERROR(DATEVALUE(TRIM(MID(SUBSTITUTE(I8,";",REPT(" ",50)),101,50))),0),IFERROR(DATEVALUE(TRIM(MID(SUBSTITUTE(I8,";",REPT(" ",50)),151,50))),0),IFERROR(DATEVALUE(TRIM(MID(SUBSTITUTE(I8,";",REPT(" ",50)),201,50))),0),IFERROR(DATEVALUE(TRIM(MID(SUBSTITUTE(I8,";",REPT(" ",50)),251,50))),0),IFERROR(DATEVALUE(TRIM(MID(SUBSTITUTE(I8,";",REPT(" ",50)),301,50))),0),IFERROR(DATEVALUE(TRIM(MID(SUBSTITUTE(I8,";",REPT(" ",50)),351,50))),0),IFERROR(DATEVALUE(TRIM(MID(SUBSTITUTE(I8,";",REPT(" ",50)),401,50))),0),IFERROR(DATEVALUE(TRIM(MID(SUBSTITUTE(I8,";",REPT(" ",50)),451,50))),0))) | L8: =IF(K8="","",TODAY()-K8) | M8: Operational–Medium | N8: =IF(M8="","",IF(L8="",INDEX($F$92:$F$95,MATCH(M8,$C$92:$C$95,0)),IF(L8<=INDEX($D$92:$D$95,MATCH(M8,$C$92:$C$95,0)),0,IF(L8<=INDEX($E$92:$E$95,MATCH(M8,$C$92:$C$95,0)),INDEX($F$92:$F$95,MATCH(M8,$C$92:$C$95,0)),INDEX($G$92:$G$95,MATCH(M8,$C$92:$C$95,0)))))) -> 3 | O8: =G8+N8 -> 13.5 | P8: =IF(AND(ISNUMBER(SEARCH("Speculator",C8)),E7=20),"Review Required","No Review") -> No Review | Q8: Escalate only if speculative demand dominates AND no real use cases exist (A1.4 = 0 items). | R8: AVAX is broadly used by retail users for transfers, DeFi, and dApps on Avalanche, making them the primary group. Developers are significant users via gas, deployment, and protocol tooling. Speculators are present but, relative to core network usage and builder activity, are best characterized as a minor group for this classification exercise.
A9: A1-N | B9: ≤120-word narrative summary for A.1 (purpose & design). | C9: AVAX is the native utility token of the Avalanche Primary Network, designed to secure a high‑throughput, proof‑of‑stake, Snowman/Avalanche‑based blockchain platform. AVAX’s primary purposes are to pay transaction and subnet fees, provide the staking collateral that secures validators and delegators, and serve as the unit of account across Avalanche L1s and subnets. Supply is hard‑capped at 720M AVAX, with about half minted at genesis and the remainder issued as staking rewards. All base transaction fees are paid in AVAX and burned, aligning tokenholder incentives with network usage and security. | D9: High | E9: 0 | F9: =IF(D9="High",0,IF(D9="Medium",0.05,IF(D9="Low",0.1,IF(D9="Unknown",0.15,"")))) -> 0 | G9: =E9*(1+F9) -> 0 | H9: https://build.avax.network/docs/primary-network/avax-token; https://support.avax.network/en/articles/6912428-tokenomics-faq; https://www.cube.exchange/what-is/avalanche | I9: 2024-10-15; 2024-10-01; 2025-12-01 | J9: 2025-12-12; 2025-12-12; 2025-12-12 | K9: =IF(I9="","",MAX(IFERROR(DATEVALUE(TRIM(MID(SUBSTITUTE(I9,";",REPT(" ",50)),1,50))),0),IFERROR(DATEVALUE(TRIM(MID(SUBSTITUTE(I9,";",REPT(" ",50)),51,50))),0),IFERROR(DATEVALUE(TRIM(MID(SUBSTITUTE(I9,";",REPT(" ",50)),101,50))),0),IFERROR(DATEVALUE(TRIM(MID(SUBSTITUTE(I9,";",REPT(" ",50)),151,50))),0),IFERROR(DATEVALUE(TRIM(MID(SUBSTITUTE(I9,";",REPT(" ",50)),201,50))),0),IFERROR(DATEVALUE(TRIM(MID(SUBSTITUTE(I9,";",REPT(" ",50)),251,50))),0),IFERROR(DATEVALUE(TRIM(MID(SUBSTITUTE(I9,";",REPT(" ",50)),301,50))),0),IFERROR(DATEVALUE(TRIM(MID(SUBSTITUTE(I9,";",REPT(" ",50)),351,50))),0),IFERROR(DATEVALUE(TRIM(MID(SUBSTITUTE(I9,";",REPT(" ",50)),401,50))),0),IFERROR(DATEVALUE(TRIM(MID(SUBSTITUTE(I9,";",REPT(" ",50)),451,50))),0))) -> 45992 | L9: =IF(K9="","",TODAY()-K9) -> 12 | M9: Evergreen–No Penalty | N9: =IF(M9="","",IF(L9="",INDEX($F$92:$F$95,MATCH(M9,$C$92:$C$95,0)),IF(L9<=INDEX($D$92:$D$95,MATCH(M9,$C$92:$C$95,0)),0,IF(L9<=INDEX($E$92:$E$95,MATCH(M9,$C$92:$C$95,0)),INDEX($F$92:$F$95,MATCH(M9,$C$92:$C$95,0)),INDEX($G$92:$G$95,MATCH(M9,$C$92:$C$95,0)))))) -> 0 | O9: =G9+N9 -> 0 | P9: No Review | Q9: Informational only; no trigger. | R9: Summary focuses on AVAX’s role in fees, staking-based security, unit of account across L1s/subnets, capped supply, and fee burn, all of which are clearly described in Avalanche’s official docs and tokenomics FAQs. These directly support the described purpose and design of the token.
A11: A2.1 | B11: Is the token required for core protocol operation? (Yes / Partially / No). | C11: Yes | D11: High | E11: =IF(C11="Yes",0,IF(C11="Partially",10,IF(C11="No",20,""))) -> 0 | F11: =IF(D11="High",0,IF(D11="Medium",0.05,IF(D11="Low",0.1,IF(D11="Unknown",0.15,"")))) -> 0 | G11: =E11*(1+F11) -> 0 | H11: https://build.avax.network/docs/primary-network/avax-token; https://support.avax.network/en/articles/6187511-validator-faq; https://support.avax.network/en/articles/6912428-tokenomics-faq | I11: 2024-11-15; 2024-10-01; 2024-10-01 | J11: 2025-12-12; 2025-12-12; 2025-12-12 | K11: =IF(I11="","",MAX(IFERROR(DATEVALUE(TRIM(MID(SUBSTITUTE(I11,";",REPT(" ",50)),1,50))),0),IFERROR(DATEVALUE(TRIM(MID(SUBSTITUTE(I11,";",REPT(" ",50)),51,50))),0),IFERROR(DATEVALUE(TRIM(MID(SUBSTITUTE(I11,";",REPT(" ",50)),101,50))),0),IFERROR(DATEVALUE(TRIM(MID(SUBSTITUTE(I11,";",REPT(" ",50)),151,50))),0),IFERROR(DATEVALUE(TRIM(MID(SUBSTITUTE(I11,";",REPT(" ",50)),201,50))),0),IFERROR(DATEVALUE(TRIM(MID(SUBSTITUTE(I11,";",REPT(" ",50)),251,50))),0),IFERROR(DATEVALUE(TRIM(MID(SUBSTITUTE(I11,";",REPT(" ",50)),301,50))),0),IFERROR(DATEVALUE(TRIM(MID(SUBSTITUTE(I11,";",REPT(" ",50)),351,50))),0),IFERROR(DATEVALUE(TRIM(MID(SUBSTITUTE(I11,";",REPT(" ",50)),401,50))),0),IFERROR(DATEVALUE(TRIM(MID(SUBSTITUTE(I11,";",REPT(" ",50)),451,50))),0))) -> 45611 | L11: =IF(K11="","",TODAY()-K11) -> 393 | M11: Evergreen–No Penalty | N11: =IF(M11="","",IF(L11="",INDEX($F$92:$F$95,MATCH(M11,$C$92:$C$95,0)),IF(L11<=INDEX($D$92:$D$95,MATCH(M11,$C$92:$C$95,0)),0,IF(L11<=INDEX($E$92:$E$95,MATCH(M11,$C$92:$C$95,0)),INDEX($F$92:$F$95,MATCH(M11,$C$92:$C$95,0)),INDEX($G$92:$G$95,MATCH(M11,$C$92:$C$95,0)))))) -> 0 | O11: =G11+N11 -> 0 | P11: No Review | R11: AVAX is the native utility token of the Avalanche Primary Network and is used to pay transaction fees (gas) and to secure the network via proof-of-stake validator staking. Validators must stake AVAX to participate in consensus, and all Primary Network gas fees are paid in AVAX and burned. These roles are intrinsic to core protocol operation, so the token is required rather than optional.
